## A - Bloque `finally`

**Definición:**  
El bloque `finally` es una cláusula opcional del `try` que se ejecuta **siempre**, sin importar si ocurrió una excepción o no. Es ideal para realizar acciones de limpieza, como liberar recursos (archivos, conexiones de red, etc.), que deben ejecutarse en cualquier caso.

**Ejemplo:**

```python
try:
    raise KeyboardInterrupt
finally:
    print('Goodbye, world!')
```

**Descripción del ejemplo:**

1.  Dentro del bloque `try`, lanzamos una excepción `KeyboardInterrupt`.
2.  Aunque se lanza una excepción, el bloque `finally` se ejecuta y muestra el mensaje `'Goodbye, world!'`.
3.  La excepción se propaga después de que el `finally` haya terminado.

---

## B - Comportamiento de `finally` con Excepciones

**Definición:**

- Si ocurre una excepción en el bloque `try` y no se maneja con un `except`, el bloque `finally` se ejecuta antes de que la excepción se propague.
- Si ocurre una excepción en un bloque `except` o `else`, el `finally` se ejecuta antes de que la excepción se propague.
- Si el bloque `finally` contiene un `return`, `break` o `continue`, la excepción no se propaga.

**Ejemplo:**

```python
def divide(x, y):
    try:
        result = x / y
    except ZeroDivisionError:
        print("division by zero!")
    else:
        print("result is", result)
    finally:
        print("executing finally clause")

divide(2, 1)  # Resultado: 2.0
divide(2, 0)  # División por cero
divide("2", "1")  # TypeError
```

**Descripción del ejemplo:**

1.  En `divide(2, 1)`, no hay excepciones, se ejecutan los bloques `else` y `finally`.
2.  En `divide(2, 0)`, ocurre una `ZeroDivisionError`, se ejecuta el bloque `except` y luego el `finally`.
3.  En `divide("2", "1")`, ocurre un `TypeError`, que no se maneja, pero el `finally` se ejecuta antes de propagar la excepción.

---

## C - `finally` con `return`, `break` o `continue`

**Definición:**

- Si el bloque `finally` contiene un `return`, `break` o `continue`, estos tienen prioridad sobre cualquier excepción o valor de retorno en el bloque `try`.
- Si el `finally` tiene un `return`, este será el valor retornado, ignorando cualquier `return` en el `try`.

**Ejemplo:**

```python
def bool_return():
    try:
        return True
    finally:
        return False

print(bool_return())  # Output: False
```

**Descripción del ejemplo:**

1.  El bloque `try` intenta retornar `True`.
2.  El bloque `finally` retorna `False`, lo que anula el `return` del `try`.
3.  La función retorna `False`.

---

## D - Uso Común de `finally`

**Definición:**  
En aplicaciones reales, el bloque `finally` se usa comúnmente para liberar recursos externos, como cerrar archivos o conexiones de red, asegurando que estos recursos se liberen incluso si ocurre un error.

**Ejemplo:**

```python
file = open("archivo.txt", "r")
try:
    contenido = file.read()
    print(contenido)
finally:
    file.close()
    print("Archivo cerrado.")
```

**Descripción del ejemplo:**

1.  Abrimos un archivo en modo lectura.
2.  Intentamos leer su contenido.
3.  El bloque `finally` asegura que el archivo se cierre, incluso si ocurre una excepción durante la lectura.

---

## Resumen del Cheat Sheet

1.  **`finally`**: Se ejecuta siempre, sin importar si hay una excepción o no.
2.  **Comportamiento con excepciones**: El `finally` se ejecuta antes de propagar excepciones no manejadas.
3.  **`return`, `break`, `continue` en `finally`**: Anulan cualquier excepción o retorno en el `try`.
4.  **Uso común**: Liberar recursos externos (archivos, conexiones, etc.).
