## A - Manejo de Errores con Promesas

#### 1. **Definicion:**

Las cadenas de promesas son excelentes para el manejo de errores. Cuando una promesa es rechazada, el control salta al manejador de rechazo más cercano. Esto es muy útil en la práctica, ya que permite centralizar el manejo de errores en un solo lugar.

#### 2. **Ejemplo:**

```javascript
fetch("https://no-such-server.blabla") // rejects
  .then((response) => response.json())
  .catch((err) => alert(err)); // TypeError: failed to fetch (the text may vary)
```

**Explicación del ejemplo**:
En este ejemplo, la URL de `fetch` es incorrecta, lo que provoca que la promesa sea rechazada. El `.catch` captura este error y muestra una alerta. No es necesario que el `.catch` esté inmediatamente después de la promesa que falla; puede aparecer después de varios `.then`.

## B - `try...catch` Implícito

#### 1. **Definicion:**

El código dentro de un executor de promesa y los manejadores `.then` tienen un "invisible `try...catch`" a su alrededor. Si ocurre una excepción, se captura y se trata como un rechazo de la promesa.

#### 2. **Ejemplo:**

```javascript
new Promise((resolve, reject) => {
  throw new Error("Whoops!");
}).catch(alert); // Error: Whoops!
```

**Explicación del ejemplo**:
Este código es equivalente a usar `reject(new Error("Whoops!"))`. El `try...catch` implícito captura el error y lo convierte en una promesa rechazada. Esto también ocurre dentro de los manejadores `.then`. Si lanzamos un error dentro de un `.then`, la promesa se rechaza y el control salta al manejador de errores más cercano.

## C - Relanzar Errores (Rethrowing)

#### 1. **Definicion:**

Al igual que en un `try...catch` regular, podemos analizar un error en un `.catch` y relanzarlo si no podemos manejarlo. Si lanzamos un error dentro de un `.catch`, el control pasa al siguiente manejador de errores más cercano. Si manejamos el error y terminamos normalmente, el control pasa al siguiente `.then` exitoso.

#### 2. **Ejemplo:**

```javascript
// the execution: catch -> then
new Promise((resolve, reject) => {
  throw new Error("Whoops!");
})
  .catch(function (error) {
    alert("The error is handled, continue normally");
  })
  .then(() => alert("Next successful handler runs"));
```

**Explicación del ejemplo**:
Aquí, el `.catch` maneja el error y termina normalmente, por lo que el siguiente `.then` se ejecuta.

```javascript
// the execution: catch -> catch
new Promise((resolve, reject) => {
  throw new Error("Whoops!");
})
  .catch(function (error) {
    // (*)
    if (error instanceof URIError) {
      // handle it
    } else {
      alert("Can't handle such error");
      throw error; // throwing this or another error jumps to the next catch
    }
  })
  .then(function () {
    /* doesn't run here */
  })
  .catch((error) => {
    // (**)
    alert(`The unknown error has occurred: ${error}`);
    // don't return anything => execution goes the normal way
  });
```

**Explicación del ejemplo**:
En este caso, el primer `.catch` no puede manejar el error y lo relanza, por lo que el control pasa al siguiente `.catch` en la cadena.

## D - Rechazos No Manejados (Unhandled Rejections)

#### 1. **Definicion:**

Si una promesa es rechazada y no hay un `.catch` en la cadena para manejar el error, el error se "atasca". El motor de JavaScript rastrea estos rechazos y genera un error global. En el navegador, podemos capturar estos errores usando el evento `unhandledrejection`.

#### 2. **Ejemplo:**

```javascript
window.addEventListener("unhandledrejection", function (event) {
  // the event object has two special properties:
  alert(event.promise); // [object Promise] - the promise that generated the error
  alert(event.reason); // Error: Whoops! - the unhandled error object
});

new Promise(function () {
  throw new Error("Whoops!");
}); // no catch to handle the error
```

**Explicación del ejemplo**:
Este código muestra cómo capturar un rechazo no manejado usando el evento `unhandledrejection`. El evento proporciona información sobre la promesa que generó el error y el error en sí.
