## A - Rechazos de Promesas No Controlados

#### 1. **Definición:**

Un rechazo de promesa no controlado ocurre cuando una promesa falla (es rechazada) y no hay un `.catch` en la cadena de promesas para manejar ese error. En otras palabras, el error se "escapa" y no es capturado por ningún manejador de errores. Esto puede llevar a que tu aplicación se comporte de manera inesperada o incluso se detenga sin darte una pista clara de por qué.

#### 2. **Ejemplo:**

```javascript
// Ejemplo de una promesa que puede fallar
function obtenerUsuario(id) {
  return new Promise((resolve, reject) => {
    if (id === 1) {
      resolve({ nombre: "John", isAlive: false });
    } else {
      reject("Usuario no encontrado");
    }
  });
}

// Ejemplo de una promesa que NO maneja el error
obtenerUsuario(1).then((usuario) => {
  if (!usuario.isAlive) {
    throw new Error("¡Ahhhh! El usuario está muerto"); // Este error se escapa
  }
  console.log("Usuario:", usuario.nombre);
});

// Este error NO será capturado por un try/catch normal
try {
  obtenerUsuario(2).then((usuario) => {
    console.log("Usuario:", usuario.nombre);
  });
} catch (error) {
  console.error("Error capturado:", error); // Este bloque NO capturará el error de la promesa
}
```

**Explicación del ejemplo:**
En el primer caso, si `johnSnow.isAlive` es `false`, se lanza un error, pero como no hay un `.catch`, este error se "pierde". En el segundo caso, el `try/catch` no captura el error de la promesa, ya que este ocurre dentro de la promesa y no en el flujo síncrono.

#### 3. **Notas o advertencias:**

- Los errores en promesas sin `.catch` no son capturados por los manejadores de errores tradicionales (`try/catch`).
- Las versiones recientes de Node.js emiten una advertencia cuando ocurre un rechazo no controlado, pero esto no es una solución de manejo de errores.

---

## B - Solución: `process.on('unhandledRejection', callback)`

#### 1. **Definición:**

Para evitar que los rechazos de promesas no controlados se "escapen", puedes usar `process.on('unhandledRejection', callback)`. Este evento se dispara cuando una promesa es rechazada y no hay un `.catch` en la cadena. El `callback` es una función que se ejecuta cuando ocurre este evento, permitiéndote manejar el error de manera centralizada.

#### 2. **Ejemplo:**

```javascript
process.on("unhandledRejection", (reason, promise) => {
  console.error("Rechazo de promesa no controlado:", reason);
  // Aquí puedes hacer algo con el error, como registrarlo o notificarlo
  throw reason; // Re-lanzamos el error para que lo capture el manejador de uncaughtException
});

process.on("uncaughtException", (error) => {
  console.error("Error no capturado:", error);
  // Aquí puedes manejar el error y decidir si reiniciar la aplicación
  // errorManagement.handler.handleError(error);
  // if (!errorManagement.handler.isTrustedError(error))
  //   process.exit(1);
});

function obtenerUsuario(id) {
  return new Promise((resolve, reject) => {
    if (id === 1) {
      resolve({ nombre: "John", isAlive: false });
    } else {
      reject("Usuario no encontrado");
    }
  });
}

obtenerUsuario(1).then((usuario) => {
  if (!usuario.isAlive) {
    throw new Error("¡Ahhhh! El usuario está muerto"); // Este error será capturado por unhandledRejection
  }
  console.log("Usuario:", usuario.nombre);
});
```

**Explicación del ejemplo:**
Ahora, cuando la promesa en `obtenerUsuario(1)` lanza un error, `process.on('unhandledRejection')` lo captura, lo registra y lo re-lanza para que lo capture el manejador de `uncaughtException`.

#### 3. **Notas o advertencias:**

- Es una buena práctica usar `process.on('unhandledRejection')` como un mecanismo de respaldo para manejar errores de promesas que no fueron capturados localmente.
- Asegúrate de registrar los errores y tomar las medidas necesarias para evitar que tu aplicación se detenga inesperadamente.
- En el ejemplo, se re-lanza el error para que lo capture el manejador de `uncaughtException`, que es el encargado de manejar errores no controlados en general.

---

## C - `process.on('uncaughtException', callback)`

#### 1. **Definición:**

`process.on('uncaughtException', callback)` es un evento que se dispara cuando ocurre un error que no es capturado por ningún `try/catch` o manejador de errores. Es un mecanismo de último recurso para manejar errores inesperados en tu aplicación.

#### 2. **Ejemplo:**

```javascript
process.on("uncaughtException", (error) => {
  console.error("Error no capturado:", error);
  // Aquí puedes manejar el error y decidir si reiniciar la aplicación
  // errorManagement.handler.handleError(error);
  // if (!errorManagement.handler.isTrustedError(error))
  //   process.exit(1);
});

throw new Error("Este error no será capturado por un try/catch");
```

**Explicación del ejemplo:**
En este ejemplo, el error lanzado no es capturado por ningún `try/catch`, por lo que `process.on('uncaughtException')` lo captura y lo registra.

#### 3. **Notas o advertencias:**

- Es importante usar `process.on('uncaughtException')` con precaución, ya que puede enmascarar errores y dificultar la depuración.
- En general, es mejor manejar los errores de manera más específica, usando `try/catch` y `.catch` en las promesas.
- `process.on('uncaughtException')` debe usarse como un último recurso para evitar que tu aplicación se detenga inesperadamente.

---

## D - La Importancia de `.catch` en Promesas

#### 1. **Definición:**

El método `.catch` en promesas es esencial para manejar los errores que puedan ocurrir durante la ejecución de una promesa. Si una promesa es rechazada y no hay un `.catch` en la cadena, el error se "escapa" y puede causar problemas en tu aplicación.

#### 2. **Ejemplo:**

```javascript
function obtenerUsuario(id) {
  return new Promise((resolve, reject) => {
    if (id === 1) {
      resolve({ nombre: "John", isAlive: false });
    } else {
      reject("Usuario no encontrado");
    }
  });
}

obtenerUsuario(1)
  .then((usuario) => {
    if (!usuario.isAlive) {
      throw new Error("¡Ahhhh! El usuario está muerto");
    }
    console.log("Usuario:", usuario.nombre);
  })
  .catch((error) => {
    console.error("Error capturado:", error); // Este bloque capturará el error
  });

obtenerUsuario(2)
  .then((usuario) => {
    console.log("Usuario:", usuario.nombre);
  })
  .catch((error) => {
    console.error("Error capturado:", error); // Este bloque capturará el error
  });
```

**Explicación del ejemplo:**
En este ejemplo, el `.catch` captura cualquier error que ocurra en la cadena de promesas, ya sea un error lanzado explícitamente con `throw` o un rechazo de la promesa.

#### 3. **Notas o advertencias:**

- Siempre debes agregar un `.catch` al final de cada cadena de promesas para manejar los errores de manera adecuada.
- El `.catch` te permite registrar los errores, notificar a los usuarios o tomar otras medidas necesarias para evitar que tu aplicación se detenga inesperadamente.

---

## E - Ejemplo de James Nelson

#### 1. **Definición:**

El ejemplo de James Nelson ilustra cómo los errores en promesas pueden ser fácilmente ignorados si no se manejan correctamente. Muestra que incluso errores que parecen obvios pueden no ser capturados por los manejadores de errores tradicionales.

#### 2. **Ejemplo:**

```javascript
Promise.resolve("promised value").then(() => {
  throw new Error("error"); // Este error se escapa si no hay un .catch
});

Promise.reject("error value").catch(() => {
  throw new Error("error"); // Este error se escapa si no hay un .catch
});

new Promise((resolve, reject) => {
  throw new Error("error"); // Este error se escapa si no hay un .catch
});
```

**Explicación del ejemplo:**
En este ejemplo, ninguno de los errores es capturado por un `try/catch` tradicional, y si no hay un `.catch` en la cadena de promesas, los errores se "escapan".

#### 3. **Notas o advertencias:**

- Este ejemplo destaca la importancia de manejar los errores de promesas de manera explícita, usando `.catch` y `process.on('unhandledRejection')`.
- Es fácil cometer errores al trabajar con promesas, por lo que es importante ser cuidadoso y seguir las mejores prácticas.
